Workbook
Name KPI_Margin: Pivot_Table!$D$4
Name KPI_Profit: Pivot_Table!$C$4
Name KPI_Quantity: Pivot_Table!$E$4
Name KPI_Revenue: Pivot_Table!$B$4
Name ShoeSalesCopy: Table1[]
Name Slicer_Brand_Cleaned: #N/A
Name Slicer_Category_Cleaned: #N/A

Sheet Business Questions
A1: Business Questions:
A3: 1 | B3: How is the business performing overall?
A5: 2 | B5: 2. How have revenue and profit changed over time?
A7: 3 | B7: 3. Which products are driving sales?
A9: 4 | B9: 4. Which products are driving profitability?
A11: 5 | B11: 5. Which categories and brands perform best?
A13: 6 | B13: 6. Which countries contribute the most to the business?
A15: 7 | B15: 7. What purchasing patterns can we identify from payment method and product preferences?
A17: 8 | B17: 8. What actions should management take based on the findings?

Sheet Shoe Sales
B1: Product | C1: Category | D1: Color | E1: Brand | F1: Country | G1: Quantity | H1: Payment Type
A2: 05/19/2026 | B2: monk straps | C2: Formal | D2: Red | E2: Nike | F2: Uganda | G2: 7 | H2: Bank Transfer
A3: 06/26/2026 | B3: loafers | C3: Formal | D3: Black | E3: nike | F3: Uganda | G3: 1 | H3: Card
A4: 05/30/2026 | B4: Derby | C4: FORMAL | D4: Green | E4: clarks | F4: Nigeria | G4: 7 | H4: Bank Transfer
A5: 46333 | B5: boots | C5: UTILITY | D5: Black | E5: nike | F5: Canada | G5: 6 | H5: Bank Transfer
A6: 04/18/2026 | B6: BOOTS | C6: casual | D6: Red | E6: CLARKS | F6: UK | G6: 6 | H6: Bank Transfer
A7: 46359 | B7: Canvas | C7: Utility | D7: Blue | E7: NIKE | F7: Ghana | G7: 6 | H7: Card
A8: 06/18/2026 | B8: canvas | C8: Formal | D8: Green | E8: clarks | F8: USA | G8: 13 | H8: Cash
A9: 46272 | B9: monk straps | C9: Formal | D9: Brown | E9: timberland | F9: USA | G9: 12 | H9: Cash
A10: 01/16/2026 | B10: Derby | C10: formal | D10: Green | E10: clarks | F10: Australia | G10: 10 | H10: Cash
A11: 46271 | B11: OXFORD | C11: Formal | D11: Black | E11: clarks | F11: Cyprus | G11: 15 | H11: Mobile Money
A12: 04/20/2026 | B12: BOOTS | C12: Formal | D12: Brown | E12: Clarks | F12: India | G12: 8 | H12: Bank Transfer
A13: 03/16/2026 | B13: loafers | C13: casual | D13: Green | E13: Clarks | F13: Australia | G13: 9 | H13: Cash
A14: 46117 | B14: BROGUES | C14: UTILITY | D14: Green | E14: Nike | F14: Germany | G14: 14 | H14: Bank Transfer
A15: 46266 | B15: oxford | C15: formal | D15: Green | E15: timberland | F15: Nigeria | G15: 4 | H15: Card
A16: 06/26/2026 | B16: SLIPPERS | C16: FORMAL | D16: Red | E16: ZARA | F16: Uganda | G16: 6 | H16: Card
A17: 07/23/2026 | B17: derby | C17: Casual | D17: Green | E17: Zara | F17: Philippines | G17: 10 | H17: Cash
A18: 04/13/2026 | B18: boots | C18: OPEN | D18: Red | E18: Steve Madden | F18: Nigeria | G18: 7 | H18: Bank Transfer
A19: 05/20/2026 | B19: DERBY | C19: CASUAL | D19: Blue | E19: CLARKS | F19: UK | G19: 7 | H19: Mobile Money
A20: 03/31/2026 | B20: Oxford | C20: OPEN | D20: Black | E20: clarks | F20: UK | G20: 11 | H20: Cash
A21: 46147 | B21: boots | C21: UTILITY | D21: Red | E21: NIKE | F21: Zimbabwe | G21: 6 | H21: Cash
A22: 46211 | B22: Monk Straps | C22: Formal | D22: Red | E22: CLARKS | F22: Germany | G22: 8 | H22: Card
A23: 07/14/2026 | B23: BROGUES | C23: Casual | D23: Green | E23: Steve Madden | F23: Australia | G23: 5 | H23: Mobile Money
A24: 46357 | B24: OXFORD | C24: formal | D24: Green | E24: STEVE MADDEN | F24: Zimbabwe | G24: 15 | H24: Card
A25: 01/28/2026 | B25: Canvas | C25: FORMAL | D25: Green | E25: steve madden | F25: Cyprus | G25: 1 | H25: Card
A26: 01/13/2026 | B26: Boots | C26: CASUAL | D26: Blue | E26: Clarks | F26: Ghana | G26: 12 | H26: Cash
A27: 03/13/2026 | B27: loafers | C27: UTILITY | D27: Green | E27: Steve Madden | F27: India | G27: 9 | H27: Mobile Money
A28: 46333 | B28: oxford | C28: Formal | D28: Green | E28: clarks | F28: Ghana | G28: 5 | H28: Mobile Money
A29: 46298 | B29: loafers | C29: CASUAL | D29: Green | E29: Clarks | F29: Zimbabwe | G29: 8 | H29: Bank Transfer
A30: 04/30/2026 | B30: OXFORD | C30: formal | D30: Red | E30: zara | F30: Nigeria | G30: 2 | H30: Bank Transfer
A31: 02/15/2026 | B31: MONK STRAPS | C31: Formal | D31: Blue | E31: ZARA | F31: Albania | G31: 7 | H31: Cash
A32: 07/16/2026 | B32: brogues | C32: formal | D32: Red | E32: STEVE MADDEN | F32: Germany | G32: 12 | H32: Mobile Money
A33: 46362 | B33: Canvas | C33: formal | D33: Blue | E33: CLARKS | F33: Zimbabwe | G33: 15 | H33: Card
A34: 46061 | B34: boots | C34: FORMAL | D34: Red | E34: Zara | F34: Uganda | G34: 7 | H34: Mobile Money
A35: 03/30/2026 | B35: BROGUES | C35: formal | D35: Black | E35: nike | F35: Cyprus | G35: 10 | H35: Bank Transfer
A36: 04/20/2026 | B36: monk straps | C36: Open | D36: Green | E36: nike | F36: Philippines | G36: 7 | H36: Bank Transfer
A37: 07/25/2026 | B37: boots | C37: formal | D37: Red | E37: timberland | F37: Canada | G37: 5 | H37: Card
A38: 46087 | B38: Boots | C38: FORMAL | D38: Red | E38: Clarks | F38: India | G38: 11 | H38: Bank Transfer
A39: 07/23/2026 | B39: slippers | C39: CASUAL | D39: Red | E39: zara | F39: Zimbabwe | G39: 10 | H39: Bank Transfer
A40: 07/25/2026 | B40: loafers | C40: Open | D40: Green | E40: CLARKS | F40: USA | G40: 10 | H40: Mobile Money
...

Sheet Shoe_Sales
A1: Date | B1: Year | C1: Day | D1: Month | E1: Product Cleaned | F1: Category Cleaned | G1: Color | H1: Brand Cleaned | I1: Country | J1: Quantity | K1: Payment Type | L1: Selling Price | M1: Cost Price | N1: Total Revenue | O1: Cost | P1: Profit | Q1: Profit Margin
A2: 05/19/2026 | B2: =RIGHT(TRIM(A2), 4) -> 2026 | C2: =MID(TRIM(A2), 4, 2) -> 19 | D2: =TEXT(DATE(RIGHT(TRIM(A2), 4), LEFT(TRIM(A2), 2), MID(TRIM(A2), 4, 2)), "mmm") -> May | E2: Monk Straps | F2: Formal | G2: Red | H2: Nike | I2: Uganda | J2: 7 | K2: Bank Transfer | L2: $89.00 | M2: =VLOOKUP(E2,Price!$A$2:$C$9,3,) -> $47.00 | N2: =J2 * VALUE(SUBSTITUTE(L2,"$","")) -> 623 | O2: =J2*VALUE(SUBSTITUTE(M2,"$","")) -> 329 | P2: =N2-O2 -> 294 | Q2: =Table1[[#This Row],[Profit ]]/Table1[[#This Row],[Total Revenue]] -> 0.47191011
A3: 06/26/2026 | B3: =RIGHT(TRIM(A3), 4) -> 2026 | C3: =MID(TRIM(A3), 4, 2) -> 26 | D3: =TEXT(DATE(RIGHT(TRIM(A3), 4), LEFT(TRIM(A3), 2), MID(TRIM(A3), 4, 2)), "mmm") -> Jun | E3: Loafers | F3: Formal | G3: Black | H3: Nike | I3: Uganda | J3: 1 | K3: Card | L3: $54.00 | M3: =VLOOKUP(E3,Price!$A$2:$C$9,3,) -> $28.00 | N3: =J3 * VALUE(SUBSTITUTE(L3,"$","")) -> 54 | O3: =J3*VALUE(SUBSTITUTE(M3,"$","")) -> 28 | P3: =N3-O3 -> 26 | Q3: =Table1[[#This Row],[Profit ]]/Table1[[#This Row],[Total Revenue]] -> 0.48148148
A4: 05/30/2026 | B4: =RIGHT(TRIM(A4), 4) -> 2026 | C4: =MID(TRIM(A4), 4, 2) -> 30 | D4: =TEXT(DATE(RIGHT(TRIM(A4), 4), LEFT(TRIM(A4), 2), MID(TRIM(A4), 4, 2)), "mmm") -> May | E4: Derby | F4: Formal | G4: Green | H4: Clarks | I4: Nigeria | J4: 7 | K4: Bank Transfer | L4: $32.00 | M4: =VLOOKUP(E4,Price!$A$2:$C$9,3,) -> $14.00 | N4: =J4 * VALUE(SUBSTITUTE(L4,"$","")) -> 224 | O4: =J4*VALUE(SUBSTITUTE(M4,"$","")) -> 98 | P4: =N4-O4 -> 126 | Q4: =Table1[[#This Row],[Profit ]]/Table1[[#This Row],[Total Revenue]] -> 0.5625
A5: 46333 | B5: =RIGHT(TRIM(A5), 4) -> 6333 | C5: =MID(TRIM(A5), 4, 2) -> 33 | D5: =TEXT(DATE(RIGHT(TRIM(A5), 4), LEFT(TRIM(A5), 2), MID(TRIM(A5), 4, 2)), "mmm") -> Nov | E5: Boots | F5: Utility | G5: Black | H5: Nike | I5: Canada | J5: 6 | K5: Bank Transfer | L5: $76.00 | M5: =VLOOKUP(E5,Price!$A$2:$C$9,3,) -> $39.00 | N5: =J5 * VALUE(SUBSTITUTE(L5,"$","")) -> 456 | O5: =J5*VALUE(SUBSTITUTE(M5,"$","")) -> 234 | P5: =N5-O5 -> 222 | Q5: =Table1[[#This Row],[Profit ]]/Table1[[#This Row],[Total Revenue]] -> 0.48684211
A6: 04/18/2026 | B6: =RIGHT(TRIM(A6), 4) -> 2026 | C6: =MID(TRIM(A6), 4, 2) -> 18 | D6: =TEXT(DATE(RIGHT(TRIM(A6), 4), LEFT(TRIM(A6), 2), MID(TRIM(A6), 4, 2)), "mmm") -> Apr | E6: Boots | F6: Casual | G6: Red | H6: Clarks | I6: UK | J6: 6 | K6: Bank Transfer | L6: $76.00 | M6: =VLOOKUP(E6,Price!$A$2:$C$9,3,) -> $39.00 | N6: =J6 * VALUE(SUBSTITUTE(L6,"$","")) -> 456 | O6: =J6*VALUE(SUBSTITUTE(M6,"$","")) -> 234 | P6: =N6-O6 -> 222 | Q6: =Table1[[#This Row],[Profit ]]/Table1[[#This Row],[Total Revenue]] -> 0.48684211
A7: 46359 | B7: =RIGHT(TRIM(A7), 4) -> 6359 | C7: =MID(TRIM(A7), 4, 2) -> 59 | D7: =TEXT(DATE(RIGHT(TRIM(A7), 4), LEFT(TRIM(A7), 2), MID(TRIM(A7), 4, 2)), "mmm") -> Nov | E7: Canvas | F7: Utility | G7: Blue | H7: Nike | I7: Ghana | J7: 6 | K7: Card | L7: $128.00 | M7: =VLOOKUP(E7,Price!$A$2:$C$9,3,) -> $72.00 | N7: =J7 * VALUE(SUBSTITUTE(L7,"$","")) -> 768 | O7: =J7*VALUE(SUBSTITUTE(M7,"$","")) -> 432 | P7: =N7-O7 -> 336 | Q7: =Table1[[#This Row],[Profit ]]/Table1[[#This Row],[Total Revenue]] -> 0.4375
A8: 06/18/2026 | B8: =RIGHT(TRIM(A8), 4) -> 2026 | C8: =MID(TRIM(A8), 4, 2) -> 18 | D8: =TEXT(DATE(RIGHT(TRIM(A8), 4), LEFT(TRIM(A8), 2), MID(TRIM(A8), 4, 2)), "mmm") -> Jun | E8: Canvas | F8: Formal | G8: Green | H8: Clarks | I8: USA | J8: 13 | K8: Cash | L8: $128.00 | M8: =VLOOKUP(E8,Price!$A$2:$C$9,3,) -> $72.00 | N8: =J8 * VALUE(SUBSTITUTE(L8,"$","")) -> 1664 | O8: =J8*VALUE(SUBSTITUTE(M8,"$","")) -> 936 | P8: =N8-O8 -> 728 | Q8: =Table1[[#This Row],[Profit ]]/Table1[[#This Row],[Total Revenue]] -> 0.4375
A9: 46272 | B9: =RIGHT(TRIM(A9), 4) -> 6272 | C9: =MID(TRIM(A9), 4, 2) -> 72 | D9: =TEXT(DATE(RIGHT(TRIM(A9), 4), LEFT(TRIM(A9), 2), MID(TRIM(A9), 4, 2)), "mmm") -> Dec | E9: Monk Straps | F9: Formal | G9: Brown | H9: Timberland | I9: USA | J9: 12 | K9: Cash | L9: $89.00 | M9: =VLOOKUP(E9,Price!$A$2:$C$9,3,) -> $47.00 | N9: =J9 * VALUE(SUBSTITUTE(L9,"$","")) -> 1068 | O9: =J9*VALUE(SUBSTITUTE(M9,"$","")) -> 564 | P9: =N9-O9 -> 504 | Q9: =Table1[[#This Row],[Profit ]]/Table1[[#This Row],[Total Revenue]] -> 0.47191011
A10: 01/16/2026 | B10: =RIGHT(TRIM(A10), 4) -> 2026 | C10: =MID(TRIM(A10), 4, 2) -> 16 | D10: =TEXT(DATE(RIGHT(TRIM(A10), 4), LEFT(TRIM(A10), 2), MID(TRIM(A10), 4, 2)), "mmm") -> Jan | E10: Derby | F10: Formal | G10: Green | H10: Clarks | I10: Australia | J10: 10 | K10: Cash | L10: $32.00 | M10: =VLOOKUP(E10,Price!$A$2:$C$9,3,) -> $14.00 | N10: =J10 * VALUE(SUBSTITUTE(L10,"$","")) -> 320 | O10: =J10*VALUE(SUBSTITUTE(M10,"$","")) -> 140 | P10: =N10-O10 -> 180 | Q10: =Table1[[#This Row],[Profit ]]/Table1[[#This Row],[Total Revenue]] -> 0.5625
A11: 46271 | B11: =RIGHT(TRIM(A11), 4) -> 6271 | C11: =MID(TRIM(A11), 4, 2) -> 71 | D11: =TEXT(DATE(RIGHT(TRIM(A11), 4), LEFT(TRIM(A11), 2), MID(TRIM(A11), 4, 2)), "mmm") -> Dec | E11: Oxford | F11: Formal | G11: Black | H11: Clarks | I11: Cyprus | J11: 15 | K11: Mobile Money | L11: $105.00 | M11: =VLOOKUP(E11,Price!$A$2:$C$9,3,) -> $58.00 | N11: =J11 * VALUE(SUBSTITUTE(L11,"$","")) -> 1575 | O11: =J11*VALUE(SUBSTITUTE(M11,"$","")) -> 870 | P11: =N11-O11 -> 705 | Q11: =Table1[[#This Row],[Profit ]]/Table1[[#This Row],[Total Revenue]] -> 0.44761905
A12: 04/20/2026 | B12: =RIGHT(TRIM(A12), 4) -> 2026 | C12: =MID(TRIM(A12), 4, 2) -> 20 | D12: =TEXT(DATE(RIGHT(TRIM(A12), 4), LEFT(TRIM(A12), 2), MID(TRIM(A12), 4, 2)), "mmm") -> Apr | E12: Boots | F12: Formal | G12: Brown | H12: Clarks | I12: India | J12: 8 | K12: Bank Transfer | L12: $76.00 | M12: =VLOOKUP(E12,Price!$A$2:$C$9,3,) -> $39.00 | N12: =J12 * VALUE(SUBSTITUTE(L12,"$","")) -> 608 | O12: =J12*VALUE(SUBSTITUTE(M12,"$","")) -> 312 | P12: =N12-O12 -> 296 | Q12: =Table1[[#This Row],[Profit ]]/Table1[[#This Row],[Total Revenue]] -> 0.48684211
A13: 03/16/2026 | B13: =RIGHT(TRIM(A13), 4) -> 2026 | C13: =MID(TRIM(A13), 4, 2) -> 16 | D13: =TEXT(DATE(RIGHT(TRIM(A13), 4), LEFT(TRIM(A13), 2), MID(TRIM(A13), 4, 2)), "mmm") -> Mar | E13: Loafers | F13: Casual | G13: Green | H13: Clarks | I13: Australia | J13: 9 | K13: Cash | L13: $54.00 | M13: =VLOOKUP(E13,Price!$A$2:$C$9,3,) -> $28.00 | N13: =J13 * VALUE(SUBSTITUTE(L13,"$","")) -> 486 | O13: =J13*VALUE(SUBSTITUTE(M13,"$","")) -> 252 | P13: =N13-O13 -> 234 | Q13: =Table1[[#This Row],[Profit ]]/Table1[[#This Row],[Total Revenue]] -> 0.48148148
A14: 46117 | B14: =RIGHT(TRIM(A14), 4) -> 6117 | C14: =MID(TRIM(A14), 4, 2) -> 17 | D14: =TEXT(DATE(RIGHT(TRIM(A14), 4), LEFT(TRIM(A14), 2), MID(TRIM(A14), 4, 2)), "mmm") -> Oct | E14: Brogues | F14: Utility | G14: Green | H14: Nike | I14: Germany | J14: 14 | K14: Bank Transfer | L14: $112.00 | M14: =VLOOKUP(E14,Price!$A$2:$C$9,3,) -> $64.00 | N14: =J14 * VALUE(SUBSTITUTE(L14,"$","")) -> 1568 | O14: =J14*VALUE(SUBSTITUTE(M14,"$","")) -> 896 | P14: =N14-O14 -> 672 | Q14: =Table1[[#This Row],[Profit ]]/Table1[[#This Row],[Total Revenue]] -> 0.42857143
A15: 46266 | B15: =RIGHT(TRIM(A15), 4) -> 6266 | C15: =MID(TRIM(A15), 4, 2) -> 66 | D15: =TEXT(DATE(RIGHT(TRIM(A15), 4), LEFT(TRIM(A15), 2), MID(TRIM(A15), 4, 2)), "mmm") -> Dec | E15: Oxford | F15: Formal | G15: Green | H15: Timberland | I15: Nigeria | J15: 4 | K15: Card | L15: $105.00 | M15: =VLOOKUP(E15,Price!$A$2:$C$9,3,) -> $58.00 | N15: =J15 * VALUE(SUBSTITUTE(L15,"$","")) -> 420 | O15: =J15*VALUE(SUBSTITUTE(M15,"$","")) -> 232 | P15: =N15-O15 -> 188 | Q15: =Table1[[#This Row],[Profit ]]/Table1[[#This Row],[Total Revenue]] -> 0.44761905
A16: 06/26/2026 | B16: =RIGHT(TRIM(A16), 4) -> 2026 | C16: =MID(TRIM(A16), 4, 2) -> 26 | D16: =TEXT(DATE(RIGHT(TRIM(A16), 4), LEFT(TRIM(A16), 2), MID(TRIM(A16), 4, 2)), "mmm") -> Jun | E16: Slippers | F16: Formal | G16: Red | H16: Zara | I16: Uganda | J16: 6 | K16: Card | L16: $119.00 | M16: =VLOOKUP(E16,Price!$A$2:$C$9,3,) -> $67.00 | N16: =J16 * VALUE(SUBSTITUTE(L16,"$","")) -> 714 | O16: =J16*VALUE(SUBSTITUTE(M16,"$","")) -> 402 | P16: =N16-O16 -> 312 | Q16: =Table1[[#This Row],[Profit ]]/Table1[[#This Row],[Total Revenue]] -> 0.43697479
A17: 07/23/2026 | B17: =RIGHT(TRIM(A17), 4) -> 2026 | C17: =MID(TRIM(A17), 4, 2) -> 23 | D17: =TEXT(DATE(RIGHT(TRIM(A17), 4), LEFT(TRIM(A17), 2), MID(TRIM(A17), 4, 2)), "mmm") -> Jul | E17: Derby | F17: Casual | G17: Green | H17: Zara | I17: Philippines | J17: 10 | K17: Cash | L17: $32.00 | M17: =VLOOKUP(E17,Price!$A$2:$C$9,3,) -> $14.00 | N17: =J17 * VALUE(SUBSTITUTE(L17,"$","")) -> 320 | O17: =J17*VALUE(SUBSTITUTE(M17,"$","")) -> 140 | P17: =N17-O17 -> 180 | Q17: =Table1[[#This Row],[Profit ]]/Table1[[#This Row],[Total Revenue]] -> 0.5625
A18: 04/13/2026 | B18: =RIGHT(TRIM(A18), 4) -> 2026 | C18: =MID(TRIM(A18), 4, 2) -> 13 | D18: =TEXT(DATE(RIGHT(TRIM(A18), 4), LEFT(TRIM(A18), 2), MID(TRIM(A18), 4, 2)), "mmm") -> Apr | E18: Boots | F18: Open | G18: Red | H18: Steve Madden | I18: Nigeria | J18: 7 | K18: Bank Transfer | L18: $76.00 | M18: =VLOOKUP(E18,Price!$A$2:$C$9,3,) -> $39.00 | N18: =J18 * VALUE(SUBSTITUTE(L18,"$","")) -> 532 | O18: =J18*VALUE(SUBSTITUTE(M18,"$","")) -> 273 | P18: =N18-O18 -> 259 | Q18: =Table1[[#This Row],[Profit ]]/Table1[[#This Row],[Total Revenue]] -> 0.48684211
A19: 05/20/2026 | B19: =RIGHT(TRIM(A19), 4) -> 2026 | C19: =MID(TRIM(A19), 4, 2) -> 20 | D19: =TEXT(DATE(RIGHT(TRIM(A19), 4), LEFT(TRIM(A19), 2), MID(TRIM(A19), 4, 2)), "mmm") -> May | E19: Derby | F19: Casual | G19: Blue | H19: Clarks | I19: UK | J19: 7 | K19: Mobile Money | L19: $32.00 | M19: =VLOOKUP(E19,Price!$A$2:$C$9,3,) -> $14.00 | N19: =J19 * VALUE(SUBSTITUTE(L19,"$","")) -> 224 | O19: =J19*VALUE(SUBSTITUTE(M19,"$","")) -> 98 | P19: =N19-O19 -> 126 | Q19: =Table1[[#This Row],[Profit ]]/Table1[[#This Row],[Total Revenue]] -> 0.5625
A20: 03/31/2026 | B20: =RIGHT(TRIM(A20), 4) -> 2026 | C20: =MID(TRIM(A20), 4, 2) -> 31 | D20: =TEXT(DATE(RIGHT(TRIM(A20), 4), LEFT(TRIM(A20), 2), MID(TRIM(A20), 4, 2)), "mmm") -> Mar | E20: Oxford | F20: Open | G20: Black | H20: Clarks | I20: UK | J20: 11 | K20: Cash | L20: $105.00 | M20: =VLOOKUP(E20,Price!$A$2:$C$9,3,) -> $58.00 | N20: =J20 * VALUE(SUBSTITUTE(L20,"$","")) -> 1155 | O20: =J20*VALUE(SUBSTITUTE(M20,"$","")) -> 638 | P20: =N20-O20 -> 517 | Q20: =Table1[[#This Row],[Profit ]]/Table1[[#This Row],[Total Revenue]] -> 0.44761905
A21: 46147 | B21: =RIGHT(TRIM(A21), 4) -> 6147 | C21: =MID(TRIM(A21), 4, 2) -> 47 | D21: =TEXT(DATE(RIGHT(TRIM(A21), 4), LEFT(TRIM(A21), 2), MID(TRIM(A21), 4, 2)), "mmm") -> Nov | E21: Boots | F21: Utility | G21: Red | H21: Nike | I21: Zimbabwe | J21: 6 | K21: Cash | L21: $76.00 | M21: =VLOOKUP(E21,Price!$A$2:$C$9,3,) -> $39.00 | N21: =J21 * VALUE(SUBSTITUTE(L21,"$","")) -> 456 | O21: =J21*VALUE(SUBSTITUTE(M21,"$","")) -> 234 | P21: =N21-O21 -> 222 | Q21: =Table1[[#This Row],[Profit ]]/Table1[[#This Row],[Total Revenue]] -> 0.48684211
A22: 46211 | B22: =RIGHT(TRIM(A22), 4) -> 6211 | C22: =MID(TRIM(A22), 4, 2) -> 11 | D22: =TEXT(DATE(RIGHT(TRIM(A22), 4), LEFT(TRIM(A22), 2), MID(TRIM(A22), 4, 2)), "mmm") -> Oct | E22: Monk Straps | F22: Formal | G22: Red | H22: Clarks | I22: Germany | J22: 8 | K22: Card | L22: $89.00 | M22: =VLOOKUP(E22,Price!$A$2:$C$9,3,) -> $47.00 | N22: =J22 * VALUE(SUBSTITUTE(L22,"$","")) -> 712 | O22: =J22*VALUE(SUBSTITUTE(M22,"$","")) -> 376 | P22: =N22-O22 -> 336 | Q22: =Table1[[#This Row],[Profit ]]/Table1[[#This Row],[Total Revenue]] -> 0.47191011
A23: 07/14/2026 | B23: =RIGHT(TRIM(A23), 4) -> 2026 | C23: =MID(TRIM(A23), 4, 2) -> 14 | D23: =TEXT(DATE(RIGHT(TRIM(A23), 4), LEFT(TRIM(A23), 2), MID(TRIM(A23), 4, 2)), "mmm") -> Jul | E23: Brogues | F23: Casual | G23: Green | H23: Steve Madden | I23: Australia | J23: 5 | K23: Mobile Money | L23: $112.00 | M23: =VLOOKUP(E23,Price!$A$2:$C$9,3,) -> $64.00 | N23: =J23 * VALUE(SUBSTITUTE(L23,"$","")) -> 560 | O23: =J23*VALUE(SUBSTITUTE(M23,"$","")) -> 320 | P23: =N23-O23 -> 240 | Q23: =Table1[[#This Row],[Profit ]]/Table1[[#This Row],[Total Revenue]] -> 0.42857143
A24: 46357 | B24: =RIGHT(TRIM(A24), 4) -> 6357 | C24: =MID(TRIM(A24), 4, 2) -> 57 | D24: =TEXT(DATE(RIGHT(TRIM(A24), 4), LEFT(TRIM(A24), 2), MID(TRIM(A24), 4, 2)), "mmm") -> Nov | E24: Oxford | F24: Formal | G24: Green | H24: Steve Madden | I24: Zimbabwe | J24: 15 | K24: Card | L24: $105.00 | M24: =VLOOKUP(E24,Price!$A$2:$C$9,3,) -> $58.00 | N24: =J24 * VALUE(SUBSTITUTE(L24,"$","")) -> 1575 | O24: =J24*VALUE(SUBSTITUTE(M24,"$","")) -> 870 | P24: =N24-O24 -> 705 | Q24: =Table1[[#This Row],[Profit ]]/Table1[[#This Row],[Total Revenue]] -> 0.44761905
A25: 01/28/2026 | B25: =RIGHT(TRIM(A25), 4) -> 2026 | C25: =MID(TRIM(A25), 4, 2) -> 28 | D25: =TEXT(DATE(RIGHT(TRIM(A25), 4), LEFT(TRIM(A25), 2), MID(TRIM(A25), 4, 2)), "mmm") -> Jan | E25: Canvas | F25: Formal | G25: Green | H25: Steve Madden | I25: Cyprus | J25: 1 | K25: Card | L25: $128.00 | M25: =VLOOKUP(E25,Price!$A$2:$C$9,3,) -> $72.00 | N25: =J25 * VALUE(SUBSTITUTE(L25,"$","")) -> 128 | O25: =J25*VALUE(SUBSTITUTE(M25,"$","")) -> 72 | P25: =N25-O25 -> 56 | Q25: =Table1[[#This Row],[Profit ]]/Table1[[#This Row],[Total Revenue]] -> 0.4375
A26: 01/13/2026 | B26: =RIGHT(TRIM(A26), 4) -> 2026 | C26: =MID(TRIM(A26), 4, 2) -> 13 | D26: =TEXT(DATE(RIGHT(TRIM(A26), 4), LEFT(TRIM(A26), 2), MID(TRIM(A26), 4, 2)), "mmm") -> Jan | E26: Boots | F26: Casual | G26: Blue | H26: Clarks | I26: Ghana | J26: 12 | K26: Cash | L26: $76.00 | M26: =VLOOKUP(E26,Price!$A$2:$C$9,3,) -> $39.00 | N26: =J26 * VALUE(SUBSTITUTE(L26,"$","")) -> 912 | O26: =J26*VALUE(SUBSTITUTE(M26,"$","")) -> 468 | P26: =N26-O26 -> 444 | Q26: =Table1[[#This Row],[Profit ]]/Table1[[#This Row],[Total Revenue]] -> 0.48684211
A27: 03/13/2026 | B27: =RIGHT(TRIM(A27), 4) -> 2026 | C27: =MID(TRIM(A27), 4, 2) -> 13 | D27: =TEXT(DATE(RIGHT(TRIM(A27), 4), LEFT(TRIM(A27), 2), MID(TRIM(A27), 4, 2)), "mmm") -> Mar | E27: Loafers | F27: Utility | G27: Green | H27: Steve Madden | I27: India | J27: 9 | K27: Mobile Money | L27: $54.00 | M27: =VLOOKUP(E27,Price!$A$2:$C$9,3,) -> $28.00 | N27: =J27 * VALUE(SUBSTITUTE(L27,"$","")) -> 486 | O27: =J27*VALUE(SUBSTITUTE(M27,"$","")) -> 252 | P27: =N27-O27 -> 234 | Q27: =Table1[[#This Row],[Profit ]]/Table1[[#This Row],[Total Revenue]] -> 0.48148148
A28: 46333 | B28: =RIGHT(TRIM(A28), 4) -> 6333 | C28: =MID(TRIM(A28), 4, 2) -> 33 | D28: =TEXT(DATE(RIGHT(TRIM(A28), 4), LEFT(TRIM(A28), 2), MID(TRIM(A28), 4, 2)), "mmm") -> Nov | E28: Oxford | F28: Formal | G28: Green | H28: Clarks | I28: Ghana | J28: 5 | K28: Mobile Money | L28: $105.00 | M28: =VLOOKUP(E28,Price!$A$2:$C$9,3,) -> $58.00 | N28: =J28 * VALUE(SUBSTITUTE(L28,"$","")) -> 525 | O28: =J28*VALUE(SUBSTITUTE(M28,"$","")) -> 290 | P28: =N28-O28 -> 235 | Q28: =Table1[[#This Row],[Profit ]]/Table1[[#This Row],[Total Revenue]] -> 0.44761905
A29: 46298 | B29: =RIGHT(TRIM(A29), 4) -> 6298 | C29: =MID(TRIM(A29), 4, 2) -> 98 | D29: =TEXT(DATE(RIGHT(TRIM(A29), 4), LEFT(TRIM(A29), 2), MID(TRIM(A29), 4, 2)), "mmm") -> Jan | E29: Loafers | F29: Casual | G29: Green | H29: Clarks | I29: Zimbabwe | J29: 8 | K29: Bank Transfer | L29: $54.00 | M29: =VLOOKUP(E29,Price!$A$2:$C$9,3,) -> $28.00 | N29: =J29 * VALUE(SUBSTITUTE(L29,"$","")) -> 432 | O29: =J29*VALUE(SUBSTITUTE(M29,"$","")) -> 224 | P29: =N29-O29 -> 208 | Q29: =Table1[[#This Row],[Profit ]]/Table1[[#This Row],[Total Revenue]] -> 0.48148148
A30: 04/30/2026 | B30: =RIGHT(TRIM(A30), 4) -> 2026 | C30: =MID(TRIM(A30), 4, 2) -> 30 | D30: =TEXT(DATE(RIGHT(TRIM(A30), 4), LEFT(TRIM(A30), 2), MID(TRIM(A30), 4, 2)), "mmm") -> Apr | E30: Oxford | F30: Formal | G30: Red | H30: Zara | I30: Nigeria | J30: 2 | K30: Bank Transfer | L30: $105.00 | M30: =VLOOKUP(E30,Price!$A$2:$C$9,3,) -> $58.00 | N30: =J30 * VALUE(SUBSTITUTE(L30,"$","")) -> 210 | O30: =J30*VALUE(SUBSTITUTE(M30,"$","")) -> 116 | P30: =N30-O30 -> 94 | Q30: =Table1[[#This Row],[Profit ]]/Table1[[#This Row],[Total Revenue]] -> 0.44761905
A31: 02/15/2026 | B31: =RIGHT(TRIM(A31), 4) -> 2026 | C31: =MID(TRIM(A31), 4, 2) -> 15 | D31: =TEXT(DATE(RIGHT(TRIM(A31), 4), LEFT(TRIM(A31), 2), MID(TRIM(A31), 4, 2)), "mmm") -> Feb | E31: Monk Straps | F31: Formal | G31: Blue | H31: Zara | I31: Albania | J31: 7 | K31: Cash | L31: $89.00 | M31: =VLOOKUP(E31,Price!$A$2:$C$9,3,) -> $47.00 | N31: =J31 * VALUE(SUBSTITUTE(L31,"$","")) -> 623 | O31: =J31*VALUE(SUBSTITUTE(M31,"$","")) -> 329 | P31: =N31-O31 -> 294 | Q31: =Table1[[#This Row],[Profit ]]/Table1[[#This Row],[Total Revenue]] -> 0.47191011
A32: 07/16/2026 | B32: =RIGHT(TRIM(A32), 4) -> 2026 | C32: =MID(TRIM(A32), 4, 2) -> 16 | D32: =TEXT(DATE(RIGHT(TRIM(A32), 4), LEFT(TRIM(A32), 2), MID(TRIM(A32), 4, 2)), "mmm") -> Jul | E32: Brogues | F32: Formal | G32: Red | H32: Steve Madden | I32: Germany | J32: 12 | K32: Mobile Money | L32: $112.00 | M32: =VLOOKUP(E32,Price!$A$2:$C$9,3,) -> $64.00 | N32: =J32 * VALUE(SUBSTITUTE(L32,"$","")) -> 1344 | O32: =J32*VALUE(SUBSTITUTE(M32,"$","")) -> 768 | P32: =N32-O32 -> 576 | Q32: =Table1[[#This Row],[Profit ]]/Table1[[#This Row],[Total Revenue]] -> 0.42857143
A33: 46362 | B33: =RIGHT(TRIM(A33), 4) -> 6362 | C33: =MID(TRIM(A33), 4, 2) -> 62 | D33: =TEXT(DATE(RIGHT(TRIM(A33), 4), LEFT(TRIM(A33), 2), MID(TRIM(A33), 4, 2)), "mmm") -> Dec | E33: Canvas | F33: Formal | G33: Blue | H33: Clarks | I33: Zimbabwe | J33: 15 | K33: Card | L33: $128.00 | M33: =VLOOKUP(E33,Price!$A$2:$C$9,3,) -> $72.00 | N33: =J33 * VALUE(SUBSTITUTE(L33,"$","")) -> 1920 | O33: =J33*VALUE(SUBSTITUTE(M33,"$","")) -> 1080 | P33: =N33-O33 -> 840 | Q33: =Table1[[#This Row],[Profit ]]/Table1[[#This Row],[Total Revenue]] -> 0.4375
A34: 46061 | B34: =RIGHT(TRIM(A34), 4) -> 6061 | C34: =MID(TRIM(A34), 4, 2) -> 61 | D34: =TEXT(DATE(RIGHT(TRIM(A34), 4), LEFT(TRIM(A34), 2), MID(TRIM(A34), 4, 2)), "mmm") -> Nov | E34: Boots | F34: Formal | G34: Red | H34: Zara | I34: Uganda | J34: 7 | K34: Mobile Money | L34: $76.00 | M34: =VLOOKUP(E34,Price!$A$2:$C$9,3,) -> $39.00 | N34: =J34 * VALUE(SUBSTITUTE(L34,"$","")) -> 532 | O34: =J34*VALUE(SUBSTITUTE(M34,"$","")) -> 273 | P34: =N34-O34 -> 259 | Q34: =Table1[[#This Row],[Profit ]]/Table1[[#This Row],[Total Revenue]] -> 0.48684211
A35: 03/30/2026 | B35: =RIGHT(TRIM(A35), 4) -> 2026 | C35: =MID(TRIM(A35), 4, 2) -> 30 | D35: =TEXT(DATE(RIGHT(TRIM(A35), 4), LEFT(TRIM(A35), 2), MID(TRIM(A35), 4, 2)), "mmm") -> Mar | E35: Brogues | F35: Formal | G35: Black | H35: Nike | I35: Cyprus | J35: 10 | K35: Bank Transfer | L35: $112.00 | M35: =VLOOKUP(E35,Price!$A$2:$C$9,3,) -> $64.00 | N35: =J35 * VALUE(SUBSTITUTE(L35,"$","")) -> 1120 | O35: =J35*VALUE(SUBSTITUTE(M35,"$","")) -> 640 | P35: =N35-O35 -> 480 | Q35: =Table1[[#This Row],[Profit ]]/Table1[[#This Row],[Total Revenue]] -> 0.42857143
A36: 04/20/2026 | B36: =RIGHT(TRIM(A36), 4) -> 2026 | C36: =MID(TRIM(A36), 4, 2) -> 20 | D36: =TEXT(DATE(RIGHT(TRIM(A36), 4), LEFT(TRIM(A36), 2), MID(TRIM(A36), 4, 2)), "mmm") -> Apr | E36: Monk Straps | F36: Open | G36: Green | H36: Nike | I36: Philippines | J36: 7 | K36: Bank Transfer | L36: $89.00 | M36: =VLOOKUP(E36,Price!$A$2:$C$9,3,) -> $47.00 | N36: =J36 * VALUE(SUBSTITUTE(L36,"$","")) -> 623 | O36: =J36*VALUE(SUBSTITUTE(M36,"$","")) -> 329 | P36: =N36-O36 -> 294 | Q36: =Table1[[#This Row],[Profit ]]/Table1[[#This Row],[Total Revenue]] -> 0.47191011
A37: 07/25/2026 | B37: =RIGHT(TRIM(A37), 4) -> 2026 | C37: =MID(TRIM(A37), 4, 2) -> 25 | D37: =TEXT(DATE(RIGHT(TRIM(A37), 4), LEFT(TRIM(A37), 2), MID(TRIM(A37), 4, 2)), "mmm") -> Jul | E37: Boots | F37: Formal | G37: Red | H37: Timberland | I37: Canada | J37: 5 | K37: Card | L37: $76.00 | M37: =VLOOKUP(E37,Price!$A$2:$C$9,3,) -> $39.00 | N37: =J37 * VALUE(SUBSTITUTE(L37,"$","")) -> 380 | O37: =J37*VALUE(SUBSTITUTE(M37,"$","")) -> 195 | P37: =N37-O37 -> 185 | Q37: =Table1[[#This Row],[Profit ]]/Table1[[#This Row],[Total Revenue]] -> 0.48684211
A38: 46087 | B38: =RIGHT(TRIM(A38), 4) -> 6087 | C38: =MID(TRIM(A38), 4, 2) -> 87 | D38: =TEXT(DATE(RIGHT(TRIM(A38), 4), LEFT(TRIM(A38), 2), MID(TRIM(A38), 4, 2)), "mmm") -> Dec | E38: Boots | F38: Formal | G38: Red | H38: Clarks | I38: India | J38: 11 | K38: Bank Transfer | L38: $76.00 | M38: =VLOOKUP(E38,Price!$A$2:$C$9,3,) -> $39.00 | N38: =J38 * VALUE(SUBSTITUTE(L38,"$","")) -> 836 | O38: =J38*VALUE(SUBSTITUTE(M38,"$","")) -> 429 | P38: =N38-O38 -> 407 | Q38: =Table1[[#This Row],[Profit ]]/Table1[[#This Row],[Total Revenue]] -> 0.48684211
A39: 07/23/2026 | B39: =RIGHT(TRIM(A39), 4) -> 2026 | C39: =MID(TRIM(A39), 4, 2) -> 23 | D39: =TEXT(DATE(RIGHT(TRIM(A39), 4), LEFT(TRIM(A39), 2), MID(TRIM(A39), 4, 2)), "mmm") -> Jul | E39: Slippers | F39: Casual | G39: Red | H39: Zara | I39: Zimbabwe | J39: 10 | K39: Bank Transfer | L39: $119.00 | M39: =VLOOKUP(E39,Price!$A$2:$C$9,3,) -> $67.00 | N39: =J39 * VALUE(SUBSTITUTE(L39,"$","")) -> 1190 | O39: =J39*VALUE(SUBSTITUTE(M39,"$","")) -> 670 | P39: =N39-O39 -> 520 | Q39: =Table1[[#This Row],[Profit ]]/Table1[[#This Row],[Total Revenue]] -> 0.43697479
A40: 07/25/2026 | B40: =RIGHT(TRIM(A40), 4) -> 2026 | C40: =MID(TRIM(A40), 4, 2) -> 25 | D40: =TEXT(DATE(RIGHT(TRIM(A40), 4), LEFT(TRIM(A40), 2), MID(TRIM(A40), 4, 2)), "mmm") -> Jul | E40: Loafers | F40: Open | G40: Green | H40: Clarks | I40: USA | J40: 10 | K40: Mobile Money | L40: $54.00 | M40: =VLOOKUP(E40,Price!$A$2:$C$9,3,) -> $28.00 | N40: =J40 * VALUE(SUBSTITUTE(L40,"$","")) -> 540 | O40: =J40*VALUE(SUBSTITUTE(M40,"$","")) -> 280 | P40: =N40-O40 -> 260 | Q40: =Table1[[#This Row],[Profit ]]/Table1[[#This Row],[Total Revenue]] -> 0.48148148
...

Sheet Price
A1: Product | B1: Price | C1: Cost
A2: Monk Straps | B2: $89.00 | C2: $47.00
A3: Loafers | B3: $54.00 | C3: $28.00
A4: Derby | B4: $32.00 | C4: $14.00
A5: Boots | B5: $76.00 | C5: $39.00
A6: Canvas | B6: $128.00 | C6: $72.00
A7: Oxford | B7: $105.00 | C7: $58.00
A8: Brogues | B8: $112.00 | C8: $64.00
A9: Slippers | B9: $119.00 | C9: $67.00

Sheet Pivot_Table
B1: Overall Performance | K1: Products Profitability & Margin Performance
B3: Revenue | C3: Total Profit | D3: Total Profit Margin | E3: Total Quantity | K3: Product | L3: Total Profit | M3: % Actual_Margin
B4: 355048 | C4: 162335 | D4: 0.47075624 | E4: 4012 | K4: Derby | L4: 9396 | M4: 0.5625
K5: Boots | L5: 19980 | M5: 0.48684211
K6: Loafers | L6: 11778 | M6: 0.48148148
K7: Monk Straps | L7: 24150 | M7: 0.47191011
K8: Oxford | L8: 26367 | M8: 0.44761905
K9: Canvas | L9: 27776 | M9: 0.4375
K10: Slippers | L10: 17784 | M10: 0.43697479
K11: Brogues | L11: 25104 | M11: 0.42857143
B12: TOTAL REVENUE | D12: TOTAL PROFIT | E12: PROFIT MARGIN | G12: TOTAL UNITS | K12: Grand Total | L12: 162335 | M12: 0.45721987
B16: Performance Over Time | K16: Performance by Category & Brand
B18: Date | C18: Revenue | D18: Total Profit | K18: Category | L18: Revenue | M18: Total Profit
B19: Jan | C19: 26803 | D19: 12480 | K19: Casual | L19: 82917 | M19: 37753
B20: Feb | C20: 24097 | D20: 11060 | K20: Formal | L20: 179935 | M20: 82274
B21: Mar | C21: 27137 | D21: 12364 | K21: Open | L21: 53035 | M21: 24172
B22: Apr | C22: 28019 | D22: 12679 | K22: Utility | L22: 39161 | M22: 18136
B23: May | C23: 27142 | D23: 12359 | K23: Grand Total | L23: 355048 | M23: 162335
B24: Jun | C24: 38635 | D24: 17665
B25: Jul | C25: 34791 | D25: 15786
B26: Aug | C26: 1341 | D26: 594
B27: Sep | C27: 1493 | D27: 667 | K27: Top Countries by Revenue
B28: Oct | C28: 42974 | D28: 19633
B29: Nov | C29: 55985 | D29: 25778 | K29: Brand | L29: Revenue | M29: Total Profit
B30: Dec | C30: 46631 | D30: 21270 | K30: Casual | L30: 82917 | M30: 37753
B31: Grand Total | C31: 355048 | D31: 162335 | K31: Formal | L31: 179935 | M31: 82274
K32: Open | L32: 53035 | M32: 24172
K33: Utility | L33: 39161 | M33: 18136
K34: Grand Total | L34: 355048 | M34: 162335
B35: Revenue Generated by Product
B37: Product | C37: Revenue
B38: Derby | C38: 16704 | K38: Product vs. Payment Breakdown
B39: Loafers | C39: 24462
B40: Slippers | C40: 40698
B41: Boots | C41: 41040 | K41: Sum of Quantity | L41: Column Labels
B42: Monk Straps | C42: 51175 | K42: Product | L42: Bank Transfer | M42: Card | N42: Cash | O42: Mobile Money | P42: Grand Total
B43: Brogues | C43: 58576 | K43: Boots | L43: 145 | M43: 155 | N43: 110 | O43: 130 | P43: 540
B44: Oxford | C44: 58905 | K44: Brogues | L44: 155 | M44: 122 | N44: 126 | O44: 120 | P44: 523
B45: Canvas | C45: 63488 | K45: Canvas | L45: 174 | M45: 123 | N45: 148 | O45: 51 | P45: 496
B46: Grand Total | C46: 355048 | K46: Derby | L46: 114 | M46: 155 | N46: 143 | O46: 110 | P46: 522
...

Sheet Dashboard
B2: Overall Performance | L2: Products Profitability & Margin Performance
B8: TOTAL REVENUE | D8: TOTAL PROFIT | F8: PROFIT MARGIN | H8: TOTAL UNITS
B12: Performance Over Time
L20: Performance by Category & Brand
B30: Revenue Generated by Product
L38: Top Countries by Revenue
B48: Revenue Generated by Product
L56: Product vs. Payment Breakdown
